Workbook

Sheet Config
B3: Dev | C3: https://script.google.com/a/macros/guidewire.com/s/AKfycbyjf46mo1ApBnirDnxmh_9igX15IHnJkS__iaEEncYpK9r_3c0v7RGj9OIw6-AXWw6U/exec
A4: Call Temp Viewer | B4: Prod | C4: https://script.google.com/a/macros/guidewire.com/s/AKfycbws76mywSxgOcVNWcYZ5SsPXMLQG3JCIR9mYIbzxOPMkDguQtOVaHxWuBa3EmfxZlkF/exec
C8: Prod | D8: Tim Kennedy | E8: marketingmanager
D9: =if(C8="Prod",C4,C3) -> https://script.google.com/a/macros/guidewire.com/s/AKfycbws76mywSxgOcVNWcYZ5SsPXMLQG3JCIR9mYIbzxOPMkDguQtOVaHxWuBa3EmfxZlkF/exec
D10: =IF(D8="","","&manager="&SUBSTITUTE(D8," ","%20")) -> &manager=Tim%20Kennedy
D11: =CONCAT("?page=",E8) -> ?page=marketingmanager
C13: link w/page | D13: =concat(D9,+D11) -> https://script.google.com/a/macros/guidewire.com/s/AKfycbws76mywSxgOcVNWcYZ5SsPXMLQG3JCIR9mYIbzxOPMkDguQtOVaHxWuBa3EmfxZlkF/exec?page=marketingmanager
C14: both | D14: =concat(D13,D10) -> https://script.google.com/a/macros/guidewire.com/s/AKfycbws76mywSxgOcVNWcYZ5SsPXMLQG3JCIR9mYIbzxOPMkDguQtOVaHxWuBa3EmfxZlkF/exec?page=marketingmanager&manager=Tim%20Kennedy
C22: =concat(C21,C19)
C23: =concat(C22,C20)

Sheet GW_PartnerManagementActivities
A1: Item Name | B1: Group | C1: Board Name | D1: Partner Name | E1: Monday Item ID | F1: Board ID | G1: Activity Status | H1: Owner | I1: Assigned To | J1: Importance | K1: Activity Type | L1: Date Created | M1: Date Due | N1: Actual Completion | O1: Files | P1: Comments/Notes | Q1: Subitems | R1: Tech Board Type | S1: Alliance Manager | T1: Alliance Manager
A2: another test again | B2: Open Items | C2: Partner Management Activities | E2: 11093054347 | F2: 9791255941 | G2: In Progress | H2: Eric Apse | I2: Tim Kennedy | J2: 1. Urgent | K2: Referal | L2: 45698 | M2: 46028 | P2: just more test | R2: Partner Management Activities
A3: Make sure your parter is certified asap | B3: Open Items | C3: Partner Management Activities | E3: 10941024281 | F3: 9791255941 | G3: In Progress | H3: Eric Apse | I3: Tim Kennedy | J3: 1. Urgent | K3: Partner Management | L3: 45698 | M3: 46036 | R3: Partner Management Activities
A4: test | B4: Open Items | C4: Partner Management Activities | E4: 10809257698 | F4: 9791255941 | G4: In Progress | H4: Eric Apse | I4: Tim Kennedy | J4: 5. N/A | K4: TechAll Marketing | L4: 45698 | M4: 46037 | R4: Partner Management Activities
A5: test 2 | B5: Open Items | C5: Partner Management Activities | E5: 10813317258 | F5: 9791255941 | G5: In Progress | H5: Eric Apse | I5: Tim Kennedy | J5: 1. Urgent | K5: Marketplace | L5: 45698 | M5: 46033 | R5: Partner Management Activities
A6: test 3 | B6: Open Items | C6: Partner Management Activities | E6: 10813553846 | F6: 9791255941 | G6: In Progress | H6: Eric Apse | I6: Tim Kennedy | J6: 1. Urgent | K6: TechAll Marketing | L6: 45698 | M6: 46038 | R6: Partner Management Activities
A7: test3 new | B7: Open Items | C7: Partner Management Activities | E7: 10813549497 | F7: 9791255941 | G7: Halted | H7: Eric Apse | I7: Tim Kennedy | J7: 1. Urgent | K7: Marketplace | L7: 45698 | M7: 46038 | R7: Partner Management Activities
A8: tim test | B8: Open Items | C8: Partner Management Activities | E8: 10819625182 | F8: 9791255941 | G8: Blockers | H8: Tim Kennedy | I8: Tim Kennedy | J8: 1. Urgent | K8: Partner Management | L8: 45698 | M8: 46029 | P8: none | R8: Partner Management Activities

Sheet GW_TechOpsActivities
A1: Item Name | B1: Group | C1: Board Name | D1: Partner Name | E1: Monday Item ID | F1: Board ID | G1: Activity Status | H1: Owner | I1: Assigned To | J1: Importance | K1: Activity Type | L1: Date Created | M1: Date Due | N1: Actual Completion | O1: Files | P1: Comments/Notes | Q1: Subitems | R1: Tech Board Type | S1: Alliance Manager | T1: Alliance Manager
A2: test | B2: Open Items | C2: Tech Ops Activities | E2: 10813055615 | F2: 9791272390 | G2: In Progress | H2: Kayla Page | I2: Tim Kennedy | J2: 1. Urgent | K2: Validation | L2: 45698 | M2: 46052 | P2: none | R2: Tech Ops Activities

Sheet GW_MarketingActivities

Sheet GW_IntegrationComplianceActivit
A1: Item Name | B1: Group | C1: Board Name | D1: Partner Name | E1: Monday Item ID | F1: Board ID | G1: Activity Status | H1: Owner | I1: Assigned To | J1: Importance | K1: Activity Type | L1: Date Created | M1: Date Due | N1: Actual Completion | O1: Files | P1: Comments/Notes | Q1: Subitems | R1: Tech Board Type | S1: Alliance Manager | T1: Alliance Manager
A2: Test | B2: Open Items | C2: Integration Compliance Activities | E2: 11092783913 | F2: 18375013360 | G2: In Progress | H2: Richard Pauly | I2: Tim Kennedy | J2: 1. Urgent | K2: Partner Management | L2: 45698 | M2: 46052 | P2: test

Sheet Approvals2026
A1: Item Name | B1: Group | C1: Board Name | D1: Partner Name | E1: Monday Item ID | F1: Board ID | G1: Subitems | H1: Event URL | I1: Event Date Range and Location | J1: Decision Date By | K1: Primary Objectives | L1: Requestor | M1: Total Cost | N1: Non-participation Risks | O1: Funding Type | P1: MDF Requested | Q1: AWS MDF Requested | R1: Business Rational | S1: Strategic Fit | T1: Estimaged Attendees | U1: Named Customers/Prospects | V1: Target Personas | W1: Partner Recruitment Target | X1: Delivery Type | Y1: Overall Status | Z1: Sponsor Costs | AA1: Other Costs | AB1: AllianceManager | AC1: Partner | AD1: Market Position/Scale | AE1: Joint Customers | AF1: Integration Status | AG1: Recent joint Activities | AH1: Near Term Strategic Exploration | AI1: Event Lead (AM) | AJ1: Onsite Team | AK1: Speaker/Abstract/SessionTitle/link | AL1: Assets and Demo | AM1: SWAG Type/quantity | AN1: Other Assets | AO1: Dependencies | AP1: Requesting Department | AQ1: Partner Marketing Resources | AR1: Product Marketing Resources | AS1: Pre-event activation plan | AT1: Onsite event activation plan | AU1: Post-event activation plan | AV1: Post Event Report Due | AW1: New Leads | AX1: Meetings Held | AY1: Opportunities Created | AZ1: Pipleline $ Influenced | BA1: Boothscans | BB1: Brand/Media impressions | BC1: Customer Feedback/Testimonials | BD1: Competitive Insights | BE1: Learnings for Nextyear | BF1: Prospectus URL | BG1: Prospectus File Upload | BH1: Recommended Sponsor Tier | BI1: Other MPO | BJ1: SME Speakers | BK1: Panel Content | BL1: Industry Tradeshow/conference | BM1: Guidewire Trade Show | BN1: 1:1 Description | BO1: 1:1 Region | BP1: Event Start Date | BQ1: Create Date | BR1: Form Navigation | BS1: Scope Document Public URL | BT1: Alliance Manager
A2: Test from Tim | B2: Incoming | C2: 2026 Approvals | D2: Marketing Team | E2: 10693573595 | F2: 18389979949 | J2: 46022 | K2: Customer Story Capture, MQL Generation | L2: Tim Kennedy | N2: None | O2: Partner Funding Request | X2: Guidewire Trade Show or Conf (Partner Participation Request) | Y2: Submitted | AD2: Medium | AF2: None | BO2: n/a | BP2: 46023 | BQ2: 45994 | BR2: Exec Summary

Sheet 2026Flow
A1: Ignore | B1: Ignore | C1: Column ID | D1: Mandatory | E1: Section Grouping | F1: Group Name | G1: Monday Column | H1: Value
A2: Event Name, name | B2: =IFERROR(__xludf.DUMMYFUNCTION("ARRAYFORMULA(IF(A2:A1007="""",,SPLIT(TRIM(A2:A1007), "","")))"),"Event Name") -> Event Name | C2: =IFERROR(__xludf.DUMMYFUNCTION("""COMPUTED_VALUE""")," name") -> name | D2: TRUE | E2: Group 1 | F2: Executive Summary
A3: Event Start Date, date_mktkb5sf | B3: =IFERROR(__xludf.DUMMYFUNCTION("""COMPUTED_VALUE"""),"Event Start Date") -> Event Start Date | C3: =IFERROR(__xludf.DUMMYFUNCTION("""COMPUTED_VALUE""")," date_mktkb5sf") -> date_mktkb5sf | D3: TRUE | E3: Group 1 | F3: Executive Summary
A4: Event URL, text_mktj8ce4 | B4: =IFERROR(__xludf.DUMMYFUNCTION("""COMPUTED_VALUE"""),"Event URL") -> Event URL | C4: =IFERROR(__xludf.DUMMYFUNCTION("""COMPUTED_VALUE""")," text_mktj8ce4") -> text_mktj8ce4 | E4: Group 1 | F4: Executive Summary
A5: Decision Date By, date_mky170gm | B5: =IFERROR(__xludf.DUMMYFUNCTION("""COMPUTED_VALUE"""),"Decision Date By") -> Decision Date By | C5: =IFERROR(__xludf.DUMMYFUNCTION("""COMPUTED_VALUE""")," date_mky170gm") -> date_mky170gm | D5: TRUE | E5: Group 1 | F5: Executive Summary
A6: Event Date Range and Location, text_mktkdwry | B6: =IFERROR(__xludf.DUMMYFUNCTION("""COMPUTED_VALUE"""),"Event Date Range and Location") -> Event Date Range and Location | C6: =IFERROR(__xludf.DUMMYFUNCTION("""COMPUTED_VALUE""")," text_mktkdwry") -> text_mktkdwry | E6: Group 1 | F6: Executive Summary
A7: Primary Objectives, dropdown_mky16p7m | B7: =IFERROR(__xludf.DUMMYFUNCTION("""COMPUTED_VALUE"""),"Primary Objectives") -> Primary Objectives | C7: =IFERROR(__xludf.DUMMYFUNCTION("""COMPUTED_VALUE""")," dropdown_mky16p7m") -> dropdown_mky16p7m | D7: TRUE | E7: Group 1 | F7: Executive Summary
A8: Requestor, text_mky7xyqh | B8: =IFERROR(__xludf.DUMMYFUNCTION("""COMPUTED_VALUE"""),"Requestor") -> Requestor | C8: =IFERROR(__xludf.DUMMYFUNCTION("""COMPUTED_VALUE""")," text_mky7xyqh") -> text_mky7xyqh | E8: Group 1 | F8: Executive Summary
A9: Non-participation Risks, text_mky7njax | B9: =IFERROR(__xludf.DUMMYFUNCTION("""COMPUTED_VALUE"""),"Non-participation Risks") -> Non-participation Risks | C9: =IFERROR(__xludf.DUMMYFUNCTION("""COMPUTED_VALUE""")," text_mky7njax") -> text_mky7njax | E9: Group 1 | F9: Executive Summary
A10: Funding Type, color_mkxxef94 | B10: =IFERROR(__xludf.DUMMYFUNCTION("""COMPUTED_VALUE"""),"Funding Type") -> Funding Type | C10: =IFERROR(__xludf.DUMMYFUNCTION("""COMPUTED_VALUE""")," color_mkxxef94") -> color_mkxxef94 | D10: TRUE | E10: Group 1 | F10: Executive Summary
A11: Overall Status, status | B11: =IFERROR(__xludf.DUMMYFUNCTION("""COMPUTED_VALUE"""),"Overall Status") -> Overall Status | C11: =IFERROR(__xludf.DUMMYFUNCTION("""COMPUTED_VALUE""")," status") -> status | E11: Group 1 | F11: Executive Summary
A12: MDF Requested, color_mky7z1eq | B12: =IFERROR(__xludf.DUMMYFUNCTION("""COMPUTED_VALUE"""),"MDF Requested") -> MDF Requested | C12: =IFERROR(__xludf.DUMMYFUNCTION("""COMPUTED_VALUE""")," color_mky7z1eq") -> color_mky7z1eq | E12: Group 1 | F12: Executive Summary | G12: color_mky7z1eq | H12: MDF
A13: AWS MDF Requested, color_mky7zxp7 | B13: =IFERROR(__xludf.DUMMYFUNCTION("""COMPUTED_VALUE"""),"AWS MDF Requested") -> AWS MDF Requested | C13: =IFERROR(__xludf.DUMMYFUNCTION("""COMPUTED_VALUE""")," color_mky7zxp7") -> color_mky7zxp7 | E13: Group 1 | F13: Executive Summary | G13: color_mky7z1eq | H13: MDF
A14: Business Rational, long_text_mky25ed4 | B14: =IFERROR(__xludf.DUMMYFUNCTION("""COMPUTED_VALUE"""),"Business Rational") -> Business Rational | C14: =IFERROR(__xludf.DUMMYFUNCTION("""COMPUTED_VALUE""")," long_text_mky25ed4") -> long_text_mky25ed4 | D14: TRUE | E14: Group 2 | F14: Buisiness Rational
A15: Strategic Fit, dropdown_mky29cfy | B15: =IFERROR(__xludf.DUMMYFUNCTION("""COMPUTED_VALUE"""),"Strategic Fit") -> Strategic Fit | C15: =IFERROR(__xludf.DUMMYFUNCTION("""COMPUTED_VALUE""")," dropdown_mky29cfy") -> dropdown_mky29cfy | D15: TRUE | E15: Group 2 | F15: Buisiness Rational
A16: Estimaged Attendees, text_mky7v3a | B16: =IFERROR(__xludf.DUMMYFUNCTION("""COMPUTED_VALUE"""),"Estimaged Attendees") -> Estimaged Attendees | C16: =IFERROR(__xludf.DUMMYFUNCTION("""COMPUTED_VALUE""")," text_mky7v3a") -> text_mky7v3a | E16: Group 3 | F16: Buisiness Outcome
A17: Named Customers/Prospects, text_mky79235 | B17: =IFERROR(__xludf.DUMMYFUNCTION("""COMPUTED_VALUE"""),"Named Customers/Prospects") -> Named Customers/Prospects | C17: =IFERROR(__xludf.DUMMYFUNCTION("""COMPUTED_VALUE""")," text_mky79235") -> text_mky79235 | E17: Group 3 | F17: Buisiness Outcome
A18: Target Personas, dropdown_mky7k6qv | B18: =IFERROR(__xludf.DUMMYFUNCTION("""COMPUTED_VALUE"""),"Target Personas") -> Target Personas | C18: =IFERROR(__xludf.DUMMYFUNCTION("""COMPUTED_VALUE""")," dropdown_mky7k6qv") -> dropdown_mky7k6qv | E18: Group 3 | F18: Buisiness Outcome
A19: Partner Recruitment Target, text_mky7tsn8 | B19: =IFERROR(__xludf.DUMMYFUNCTION("""COMPUTED_VALUE"""),"Partner Recruitment Target") -> Partner Recruitment Target | C19: =IFERROR(__xludf.DUMMYFUNCTION("""COMPUTED_VALUE""")," text_mky7tsn8") -> text_mky7tsn8 | E19: Group 3 | F19: Buisiness Outcome
A20: Delivery Type, color_mky78mye | B20: =IFERROR(__xludf.DUMMYFUNCTION("""COMPUTED_VALUE"""),"Delivery Type") -> Delivery Type | C20: =IFERROR(__xludf.DUMMYFUNCTION("""COMPUTED_VALUE""")," color_mky78mye") -> color_mky78mye | D20: TRUE | E20: Group 4 | F20: Event Specific Information
A21: Prospectus URL, link_mky7wxqq | B21: =IFERROR(__xludf.DUMMYFUNCTION("""COMPUTED_VALUE"""),"Prospectus URL") -> Prospectus URL | C21: =IFERROR(__xludf.DUMMYFUNCTION("""COMPUTED_VALUE""")," link_mky7wxqq") -> link_mky7wxqq | E21: Group 4 | F21: Event Specific Information | G21: color_mky78mye | H21: Partner Trade Show/Conf - Co-Marketing Request, Partner Trade Show/Conf - Sponsor Funding
A22: Prospectus File Upload, file_mky8p6fk | B22: =IFERROR(__xludf.DUMMYFUNCTION("""COMPUTED_VALUE"""),"Prospectus File Upload") -> Prospectus File Upload | C22: =IFERROR(__xludf.DUMMYFUNCTION("""COMPUTED_VALUE""")," file_mky8p6fk") -> file_mky8p6fk | E22: Group 4 | F22: Event Specific Information | G22: color_mky78mye | H22: Partner Trade Show/Conf - Co-Marketing Request, Partner Trade Show/Conf - Sponsor Funding
A23: Recommended Sponsor Tier, text_mky76e8h | B23: =IFERROR(__xludf.DUMMYFUNCTION("""COMPUTED_VALUE"""),"Recommended Sponsor Tier") -> Recommended Sponsor Tier | C23: =IFERROR(__xludf.DUMMYFUNCTION("""COMPUTED_VALUE""")," text_mky76e8h") -> text_mky76e8h | E23: Group 4 | F23: Event Specific Information | G23: color_mky78mye | H23: Partner Trade Show/Conf - Co-Marketing Request, Partner Trade Show/Conf - Sponsor Funding
A24: Other MPO, text_mky7e8yw | B24: =IFERROR(__xludf.DUMMYFUNCTION("""COMPUTED_VALUE"""),"Other MPO") -> Other MPO | C24: =IFERROR(__xludf.DUMMYFUNCTION("""COMPUTED_VALUE""")," text_mky7e8yw") -> text_mky7e8yw | E24: Group 4 | F24: Event Specific Information | G24: color_mky78mye | H24: Partner Trade Show/Conf - Co-Marketing Request, Partner Trade Show/Conf - Sponsor Funding
A25: SME Speakers, text_mky7gcf0 | B25: =IFERROR(__xludf.DUMMYFUNCTION("""COMPUTED_VALUE"""),"SME Speakers") -> SME Speakers | C25: =IFERROR(__xludf.DUMMYFUNCTION("""COMPUTED_VALUE""")," text_mky7gcf0") -> text_mky7gcf0 | E25: Group 4 | F25: Event Specific Information | G25: color_mky78mye | H25: Partner Trade Show/Conf - Co-Marketing Request, Partner Trade Show/Conf - Sponsor Funding
A26: Panel Content, text_mky7c787 | B26: =IFERROR(__xludf.DUMMYFUNCTION("""COMPUTED_VALUE"""),"Panel Content") -> Panel Content | C26: =IFERROR(__xludf.DUMMYFUNCTION("""COMPUTED_VALUE""")," text_mky7c787") -> text_mky7c787 | E26: Group 4 | F26: Event Specific Information | G26: color_mky78mye | H26: Partner Trade Show/Conf - Co-Marketing Request, Partner Trade Show/Conf - Sponsor Funding
A27: Industry Tradeshow/conference, dropdown_mky7b5t0 | B27: =IFERROR(__xludf.DUMMYFUNCTION("""COMPUTED_VALUE"""),"Industry Tradeshow/conference") -> Industry Tradeshow/conference | C27: =IFERROR(__xludf.DUMMYFUNCTION("""COMPUTED_VALUE""")," dropdown_mky7b5t0") -> dropdown_mky7b5t0 | E27: Group 4 | F27: Event Specific Information | G27: color_mky78mye | H27: Industry Trade Show/Conf
A28: Guidewire Trade Show, dropdown_mky7qg9p | B28: =IFERROR(__xludf.DUMMYFUNCTION("""COMPUTED_VALUE"""),"Guidewire Trade Show") -> Guidewire Trade Show | C28: =IFERROR(__xludf.DUMMYFUNCTION("""COMPUTED_VALUE""")," dropdown_mky7qg9p") -> dropdown_mky7qg9p | E28: Group 4 | F28: Event Specific Information | G28: color_mky78mye | H28: Guidewire Trade Show or Conf (Partner Participation Request)
A29: 1:1 Description, text_mky7dz7 | B29: =IFERROR(__xludf.DUMMYFUNCTION("""COMPUTED_VALUE"""),"1:1 Description") -> 1:1 Description | C29: =IFERROR(__xludf.DUMMYFUNCTION("""COMPUTED_VALUE""")," text_mky7dz7") -> text_mky7dz7 | E29: Group 4 | F29: Event Specific Information | G29: dropdown_mky7b5t0 | H29: 1:1 Breakfast or Lunch Meeting
A30: 1:1 Region, color_mky7gz0q | B30: =IFERROR(__xludf.DUMMYFUNCTION("""COMPUTED_VALUE"""),"1:1 Region") -> 1:1 Region | C30: =IFERROR(__xludf.DUMMYFUNCTION("""COMPUTED_VALUE""")," color_mky7gz0q") -> color_mky7gz0q | E30: Group 4 | F30: Event Specific Information | G30: dropdown_mky7b5t0 | H30: 1:1 Breakfast or Lunch Meeting
A31: Partner, text_mkv092nh | B31: =IFERROR(__xludf.DUMMYFUNCTION("""COMPUTED_VALUE"""),"Partner") -> Partner | C31: =IFERROR(__xludf.DUMMYFUNCTION("""COMPUTED_VALUE""")," text_mkv092nh") -> text_mkv092nh | E31: Group 5 | F31: Partner Information
A32: AllianceManager, color_mky7zf8e | B32: =IFERROR(__xludf.DUMMYFUNCTION("""COMPUTED_VALUE"""),"AllianceManager") -> AllianceManager | C32: =IFERROR(__xludf.DUMMYFUNCTION("""COMPUTED_VALUE""")," color_mky7zf8e") -> color_mky7zf8e | E32: Group 5 | F32: Partner Information
A33: Sponsor Costs, numeric_mky791e | B33: =IFERROR(__xludf.DUMMYFUNCTION("""COMPUTED_VALUE"""),"Sponsor Costs") -> Sponsor Costs | C33: =IFERROR(__xludf.DUMMYFUNCTION("""COMPUTED_VALUE""")," numeric_mky791e") -> numeric_mky791e | E33: Group 5 | F33: Partner Information
A34: Other Costs, numeric_mky7r8yp | B34: =IFERROR(__xludf.DUMMYFUNCTION("""COMPUTED_VALUE"""),"Other Costs") -> Other Costs | C34: =IFERROR(__xludf.DUMMYFUNCTION("""COMPUTED_VALUE""")," numeric_mky7r8yp") -> numeric_mky7r8yp | E34: Group 5 | F34: Partner Information
A35: Market Position/Scale, color_mky76dt5 | B35: =IFERROR(__xludf.DUMMYFUNCTION("""COMPUTED_VALUE"""),"Market Position/Scale") -> Market Position/Scale | C35: =IFERROR(__xludf.DUMMYFUNCTION("""COMPUTED_VALUE""")," color_mky76dt5") -> color_mky76dt5 | E35: Group 5 | F35: Partner Information
A36: Joint Customers, text_mky7ywb2 | B36: =IFERROR(__xludf.DUMMYFUNCTION("""COMPUTED_VALUE"""),"Joint Customers") -> Joint Customers | C36: =IFERROR(__xludf.DUMMYFUNCTION("""COMPUTED_VALUE""")," text_mky7ywb2") -> text_mky7ywb2 | E36: Group 5 | F36: Partner Information
A37: Integration Status, color_mky7dc8q | B37: =IFERROR(__xludf.DUMMYFUNCTION("""COMPUTED_VALUE"""),"Integration Status") -> Integration Status | C37: =IFERROR(__xludf.DUMMYFUNCTION("""COMPUTED_VALUE""")," color_mky7dc8q") -> color_mky7dc8q | E37: Group 5 | F37: Partner Information
A38: Recent joint Activities, text_mky75gvt | B38: =IFERROR(__xludf.DUMMYFUNCTION("""COMPUTED_VALUE"""),"Recent joint Activities") -> Recent joint Activities | C38: =IFERROR(__xludf.DUMMYFUNCTION("""COMPUTED_VALUE""")," text_mky75gvt") -> text_mky75gvt | E38: Group 5 | F38: Partner Information
A39: Near Term Strategic Exploration, dropdown_mky7vh1m | B39: =IFERROR(__xludf.DUMMYFUNCTION("""COMPUTED_VALUE"""),"Near Term Strategic Exploration") -> Near Term Strategic Exploration | C39: =IFERROR(__xludf.DUMMYFUNCTION("""COMPUTED_VALUE""")," dropdown_mky7vh1m") -> dropdown_mky7vh1m | E39: Group 5 | F39: Partner Information
A40: Event Lead (AM), text_mky7mp7p | B40: =IFERROR(__xludf.DUMMYFUNCTION("""COMPUTED_VALUE"""),"Event Lead (AM)") -> Event Lead (AM) | C40: =IFERROR(__xludf.DUMMYFUNCTION("""COMPUTED_VALUE""")," text_mky7mp7p") -> text_mky7mp7p | E40: Group 6 | F40: Resourcing Plan
...

Sheet MondayData
A1: Item Name | B1: Group | C1: Board Name | D1: Partner Name | E1: Monday Item ID | F1: Board ID | G1: Subitems | H1: Comments/Notes | I1: Activity Status | J1: Owner | K1: Importance | L1: Activity | M1: Date Created | N1: Date Due | O1: Actual Completion | P1: Files | Q1: Tech Partner Name | R1: Scope Document Public URL | S1: Alliance Manager | T1: Alliance Manager
A2: Agenda for Meeting in December in London | B2: Completed Items | C2: Hyperexponential Ltd Board | D2: Hyperexponential Ltd | E2: 18387680182 | F2: 18402564488 | H2: Patrick has provided. | I2: Completed | K2: 2. High | L2: Marketing | M2: 45982 | O2: 46001 | Q2: Hyperexponential Ltd | S2: Tim Kennedy
A3: American Guaranty Fund Group | B3: Completed Items | C3: Newgen Software Inc. Board | D3: Newgen Software Inc. | E3: 9080309128 | F3: 18402565546 | H3: Newgen has submitted the proposal. waiting for customer to make decision on GW CC + Newgen ECM; In touch with Brittany. | I3: Completed | K3: 2. High | L3: Alliances | M3: 45783 | Q3: Newgen Software Inc. | S3: Tim Kennedy
A4: Ammendment needs signature for annex A | B4: Completed Items | C4: Insurance Services Office (ISO) Board | D4: Insurance Services Office (ISO) | E4: 8714057396 | F4: 18402568111 | I4: Completed | K4: 2. High | L4: Contracts | M4: 45733 | O4: 45985 | Q4: Verisk | S4: Tim Kennedy
A5: Are there sources of data we could buy from Verisk | B5: Completed Items | C5: Insurance Services Office (ISO) Board | D5: Insurance Services Office (ISO) | E5: 8821376581 | F5: 18402568111 | I5: Completed | K5: 4. Low | L5: Alliances | M5: 45747 | O5: 46010 | Q5: Verisk | S5: Tim Kennedy
A6: Ask Gilbert if his team will set up open telemetry on the Dynatrace NPE | B6: Open Items | C6: Dynatrace LLC Board | D6: Dynatrace LLC | E6: 11342942612 | F6: 18402564263 | I6: In Progress | K6: 3. Medium | L6: Sponsorship/Events | M6: 46076 | Q6: Dynatrace LLC | S6: Tim Kennedy
A7: Audit result - next steps - amend agreement on calculations | B7: Open Items | C7: Insurance Services Office (ISO) Board | D7: Insurance Services Office (ISO) | E7: 8821456844 | F7: 18402568111 | I7: SOLD | J7: GW Alliances | K7: 1. Urgent | L7: Contracts | M7: 45698 | Q7: Verisk | S7: Tim Kennedy
A8: Aviva Canada | B8: Completed Items | C8: Whatfix Inc. Board | D8: Whatfix Inc. | E8: 8671192538 | F8: 18402568372 | H8: Rebooked for May | I8: Completed | K8: 3. Medium | L8: Pipeline | M8: 45727 | O8: 45896 | Q8: Whatfix Inc. | S8: Tim Kennedy
A9: BBG TPPA Upate | B9: Open Items | C9: LexisNexis Risk Solutions Inc. Board | D9: LexisNexis Risk Solutions Inc. | E9: 18357680785 | F9: 18402564676 | H9: Tim walked the values.. they want some sort of SLA | I9: Completed | J9: Partner Alliances | K9: 1. Urgent | L9: Alliances | M9: 45966 | Q9: LexisNexis Risk Solutions Inc. | S9: Tim Kennedy
A10: Bhaskar - accelerator or not | B10: Open Items | C10: Dynatrace LLC Board | D10: Dynatrace LLC | E10: 11342940453 | F10: 18402564263 | I10: In Progress | K10: 3. Medium | L10: Sponsorship/Events | M10: 46076 | Q10: Dynatrace LLC | S10: Tim Kennedy
A11: Billing Center Accelerator | B11: Open Items | C11: Whatfix Inc. Board | D11: Whatfix Inc. | E11: 8741290643 | F11: 18402568372 | H11: We have paused this as our team is still assessing which product makes the most sense for us to build Whatfix on. | I11: Halted | J11: Partner Alliances | K11: 3. Medium | L11: Alliances | M11: 45736 | Q11: Whatfix Inc. | S11: Tim Kennedy
A12: BillingCenter Integration with Newgen ECM | B12: Completed Items | C12: Newgen Software Inc. Board | D12: Newgen Software Inc. | E12: 8464228904 | F12: 18402565546 | H12: Scope accepted. Dev in progress | I12: Completed | J12: GW Alliances, Partner Alliances | K12: 3. Medium | L12: Accelerator | M12: 45700 | Q12: Newgen Software Inc. | S12: Tim Kennedy
A13: Blog entry - Tim to edit | B13: Completed Items | C13: WTW Board | D13: WTW | E13: 9413258850 | F13: 18402568518 | I13: Completed | J13: Partner Alliances | K13: 3. Medium | L13: Marketing | M13: 45698 | N13: 46032 | Q13: WTW | S13: Tim Kennedy
A14: BOLT Next Steps & Development Plan | B14: Open Items | C14: Whatfix Inc. Board | D14: Whatfix Inc. | E14: 9849857923 | F14: 18402568372 | H14: As part of restructuring, we disolved our APAC partner team. Tony will have to get engaged. | I14: In Progress | J14: GW Alliances, Partner Alliances, GW Solution Consulting | K14: 2. High | L14: Marketing | M14: 45698 | Q14: Whatfix Inc. | S14: Tim Kennedy
A15: book Friday touch base. | B15: Completed Items | C15: SS&C Blue Prism Board | D15: SS&C Blue Prism | E15: 9035222909 | F15: 18402563983 | I15: Completed | K15: 3. Medium | L15: Alliances | M15: 45776 | O15: 46010 | Q15: Blue Prism | S15: Tim Kennedy
A16: Box - financial servicres summit | B16: Completed Items | C16: Box Board | D16: Box | E16: 18047259948 | F16: 18402563866 | H16: Paul Edwards is speaking from London Markets team | I16: Completed | K16: 2. High | L16: Alliances | M16: 45925 | O16: 45985 | Q16: Box | S16: Tim Kennedy
A17: Box wants to look at esignature | B17: Open Items | C17: Box Board | D17: Box | E17: 11379534221 | F17: 18402563866 | H17: recommend rolling it out in phases | I17: In Progress | J17: GW Alliances | K17: 2. High | L17: Accelerator | M17: 45698 | N17: 46093 | Q17: Box | S17: Tim Kennedy
A18: bundling | B18: Open Items | C18: Mitchell International, Inc. Board | D18: Mitchell International, Inc. | E18: 11428960695 | F18: 18402617065 | H18: phase 2 and phase 3 bundled as one release. | I18: In Progress | J18: Partner Alliances | K18: 2. High | L18: Alliances | M18: 45698 | S18: Tim Kennedy
A19: can we post linked in post for Whatfix premier partner press release | B19: Completed Items | C19: Whatfix Inc. Board | D19: Whatfix Inc. | E19: 10749567978 | F19: 18402568372 | H19: Asking Julie | I19: Completed | K19: 3. Medium | L19: Marketing | M19: 45698 | O19: 46010 | Q19: Whatfix Inc. | S19: Tim Kennedy
A20: Canada Webinar - | B20: Open Items | C20: Open Text Corporation Board | D20: Open Text Corporation | E20: 11377067523 | F20: 18402565219 | I20: Not Started | K20: 5. N/A | L20: Alliances | M20: 46079 | N20: 46093 | Q20: Open Text Corporation | S20: Tim Kennedy
A21: CEO Meeting | B21: Completed Items | C21: Box Board | D21: Box | E21: 18047191750 | F21: 18402563866 | H21: Intel - both agree good momentum. Mike took action to circle back with product leadership team for other product integrations. followup email thread . Will Murphy added... lets put together a workshop to elevate partnership to next level. Work with PWC and Deloitte. Conversation triggered by Safety win earlier this year. Usecase where box can extract structured content from unstructured documents and feed into Guidewire. | I21: Completed | K21: 3. Medium | L21: Alliances | M21: 45925 | O21: 45985 | Q21: Box | S21: Tim Kennedy
A22: Claims Datafill Updates | B22: Completed Items | C22: LexisNexis Risk Solutions Inc. Board | D22: LexisNexis Risk Solutions Inc. | E22: 8577093443 | F22: 18402564676 | H22: I have passed on the information to the BBG team | I22: Completed | K22: 1. Urgent | L22: Accelerator | M22: 45714 | O22: 45805 | Q22: LexisNexis Risk Solutions Inc. | S22: Tim Kennedy
A23: Closures this past year | B23: Completed Items | C23: Newgen Software Inc. Board | D23: Newgen Software Inc. | E23: 8987592914 | F23: 18402565546 | H23: Red River Mutual, QBE, Market, Adica | I23: Completed | J23: Partner Alliances | K23: 3. Medium | L23: Alliances | M23: 45770 | Q23: Newgen Software Inc. | S23: Tim Kennedy
A24: Common Customer List | B24: Completed Items | C24: AKUR8 Board | D24: AKUR8 | E24: 9412594506 | F24: 18402561158 | I24: Completed | K24: 2. High | L24: Pipeline | M24: 45827 | O24: 45985 | Q24: Akur8 | S24: Tim Kennedy
A25: Connections - gold plus | B25: Completed Items | C25: WTW Board | D25: WTW | E25: 9212952335 | F25: 18402568518 | H25: Admiral insurance. GM Financial as well | I25: Completed | K25: 3. Medium | L25: Alliances | M25: 45799 | Q25: WTW | S25: Tim Kennedy
A26: Connections meetings with Alliances and CSM | B26: Completed Items | C26: Newgen Software Inc. Board | D26: Newgen Software Inc. | E26: 9910630591 | F26: 18402565546 | H26: Swapnil wants to meet with CSMs Newgen is working with at GW Connections | I26: Completed | J26: GW Alliances | K26: 1. Urgent | L26: Sponsorship/Events | M26: 45896 | Q26: Newgen Software Inc. | S26: Tim Kennedy
A27: Countersigned Enhancements Contract | B27: Open Items | C27: Mitchell International, Inc. Board | D27: Mitchell International, Inc. | E27: 11428967324 | F27: 18402617065 | H27: Should be soon. | I27: In Progress | J27: GW Alliances | K27: 2. High | L27: Alliances | M27: 46071 | S27: Tim Kennedy
A28: CSAA | B28: Completed Items | C28: Box Board | D28: Box | E28: 18047300561 | F28: 18402563866 | I28: Completed | K28: 3. Medium | L28: Alliances | M28: 45925 | O28: 45985 | Q28: Box | S28: Tim Kennedy
A29: CSAA Police Records having problems with Police Records | B29: Completed Items | C29: LexisNexis Risk Solutions Inc. Board | D29: LexisNexis Risk Solutions Inc. | E29: 8844790265 | F29: 18402564676 | H29: Have passed it on to the BBG Team | I29: Completed | K29: 5. N/A | L29: Alliances | M29: 45749 | O29: 45805 | Q29: LexisNexis Risk Solutions Inc. | S29: Tim Kennedy
A30: CSAA- meeting with David McMinn | B30: Completed Items | C30: Newgen Software Inc. Board | D30: Newgen Software Inc. | E30: 9352347948 | F30: 18402565546 | H30: Newgen Demo scheduled; Tim to help introduce David McMinn | I30: Completed | K30: 3. Medium | L30: Alliances | M30: 45819 | Q30: Newgen Software Inc. | S30: Tim Kennedy
A31: Customer and Pipeline Report | B31: Open Items | C31: Whatfix Inc. Board | D31: Whatfix Inc. | E31: 8564192033 | F31: 18402568372 | I31: Ongoing | J31: Partner Alliances | K31: 3. Medium | L31: Marketing | M31: 45713 | Q31: Whatfix Inc. | S31: Tim Kennedy
A32: Customer and Prospect Tracker | B32: Open Items | C32: Mitchell International, Inc. Board | D32: Mitchell International, Inc. | E32: 11428971401 | F32: 18402617065 | I32: Ongoing | J32: Partner Alliances | K32: 3. Medium | L32: Pipeline | M32: 45735 | S32: Tim Kennedy
A33: Customer List | B33: Completed Items | C33: Box Board | D33: Box | E33: 9750298591 | F33: 18402563866 | H33: done | I33: Completed | K33: 3. Medium | L33: Alliances | M33: 45874 | O33: 45985 | Q33: Box | S33: Tim Kennedy
A34: Customerlist | B34: Open Items | C34: Smarty, LLC Board | D34: Smarty, LLC | E34: 9408382833 | F34: 18402567457 | I34: Ongoing | J34: Partner Alliances | K34: 2. High | L34: Pipeline | M34: 45826 | Q34: Smarty, LLC | S34: Tim Kennedy
A35: Dannon to provide training to GW Rev Team on how to update customer list. | B35: Completed Items | C35: Insurance Services Office (ISO) Board | D35: Insurance Services Office (ISO) | E35: 8608512676 | F35: 18402568111 | I35: Completed | K35: 3. Medium | L35: Contracts | M35: 45719 | O35: 46010 | Q35: Verisk | S35: Tim Kennedy
A36: Demo of Open Archive | B36: Open Items | C36: Open Text Corporation Board | D36: Open Text Corporation | E36: 11309490784 | F36: 18402565219 | I36: In Progress | K36: 3. Medium | L36: Alliances | M36: 46071 | N36: 46085 | Q36: Open Text Corporation | S36: Tim Kennedy
A37: Demo of their ECM Content Management solution | B37: Open Items | C37: Open Text Corporation Board | D37: Open Text Corporation | E37: 11309417699 | F37: 18402565219 | I37: In Progress | J37: Partner Alliances | K37: 3. Medium | L37: Accelerator | M37: 46071 | N37: 46085 | Q37: Open Text Corporation | S37: Tim Kennedy
A38: Dev Environment Upgrade to N | B38: Completed Items | C38: Whatfix Inc. Board | D38: Whatfix Inc. | E38: 8474092336 | F38: 18402568372 | H38: 12/4/24 Update: We are in the process of upgrading our GW instance to the Kufri version of Cloud, and this will be completed soon. Additionally, the version following Kufri, the Las Lenas version, is expected to be released shortly. If it becomes available soon, we plan to first upgrade to the Kufri version and then to Las Lenas. I'll update once we are done on this, as after that we can start the process to test and update the Accelerator version to Kufri on the GW Marketplace (-or Las lenas, if we update to that). | I38: Completed | K38: 1. Urgent | L38: NPE | M38: 45701 | O38: 45722 | Q38: Whatfix Inc. | S38: Tim Kennedy
A39: email on Cogniznant | B39: Completed Items | C39: Insurance Services Office (ISO) Board | D39: Insurance Services Office (ISO) | E39: 9433757764 | F39: 18402568111 | I39: Completed | K39: 5. N/A | L39: Alliances | M39: 45831 | O39: 46010 | Q39: Verisk | S39: Tim Kennedy
A40: Enablement Sessions for CSMs | B40: Open Items | C40: Newgen Software Inc. Board | D40: Newgen Software Inc. | E40: 9765924707 | F40: 18402565546 | I40: Not Started | J40: GW Alliances, Partner Alliances | K40: 2. High | L40: Alliances | M40: 45876 | Q40: Newgen Software Inc. | S40: Tim Kennedy
...

Sheet GWMondayData
A1: =IFERROR(__xludf.DUMMYFUNCTION("QUERY({GW_PartnerManagementActivities!A:Z;GW_TechOpsActivities!A2:Z999;GW_MarketingActivities!A2:Z999;GW_MarketplaceActivities!A2:Z999}, ""SELECT * WHERE Col1 IS NOT NULL"", 1)"),"Item Name") -> Item Name | B1: =IFERROR(__xludf.DUMMYFUNCTION("""COMPUTED_VALUE"""),"Group") -> Group | C1: =IFERROR(__xludf.DUMMYFUNCTION("""COMPUTED_VALUE"""),"Board Name") -> Board Name | D1: =IFERROR(__xludf.DUMMYFUNCTION("""COMPUTED_VALUE"""),"Partner Name") -> Partner Name | E1: =IFERROR(__xludf.DUMMYFUNCTION("""COMPUTED_VALUE"""),"Monday Item ID") -> Monday Item ID | F1: =IFERROR(__xludf.DUMMYFUNCTION("""COMPUTED_VALUE"""),"Board ID") -> Board ID | G1: =IFERROR(__xludf.DUMMYFUNCTION("""COMPUTED_VALUE"""),"Activity Status") -> Activity Status | H1: =IFERROR(__xludf.DUMMYFUNCTION("""COMPUTED_VALUE"""),"Owner") -> Owner | I1: =IFERROR(__xludf.DUMMYFUNCTION("""COMPUTED_VALUE"""),"Assigned To") -> Assigned To | J1: =IFERROR(__xludf.DUMMYFUNCTION("""COMPUTED_VALUE"""),"Importance") -> Importance | K1: =IFERROR(__xludf.DUMMYFUNCTION("""COMPUTED_VALUE"""),"Activity Type") -> Activity Type | L1: =IFERROR(__xludf.DUMMYFUNCTION("""COMPUTED_VALUE"""),"Date Created") -> Date Created | M1: =IFERROR(__xludf.DUMMYFUNCTION("""COMPUTED_VALUE"""),"Date Due") -> Date Due | N1: =IFERROR(__xludf.DUMMYFUNCTION("""COMPUTED_VALUE"""),"Actual Completion") -> Actual Completion | O1: =IFERROR(__xludf.DUMMYFUNCTION("""COMPUTED_VALUE"""),"Files") -> Files | P1: =IFERROR(__xludf.DUMMYFUNCTION("""COMPUTED_VALUE"""),"Comments/Notes") -> Comments/Notes | Q1: =IFERROR(__xludf.DUMMYFUNCTION("""COMPUTED_VALUE"""),"Subitems") -> Subitems | R1: =IFERROR(__xludf.DUMMYFUNCTION("""COMPUTED_VALUE"""),"Tech Board Type") -> Tech Board Type | S1: =IFERROR(__xludf.DUMMYFUNCTION("""COMPUTED_VALUE"""),"Alliance Manager") -> Alliance Manager | T1: =IFERROR(__xludf.DUMMYFUNCTION("""COMPUTED_VALUE"""),"Alliance Manager") -> Alliance Manager | U1: =IFERROR(__xludf.DUMMYFUNCTION("""COMPUTED_VALUE"""),"") | V1: =IFERROR(__xludf.DUMMYFUNCTION("""COMPUTED_VALUE"""),"") | W1: =IFERROR(__xludf.DUMMYFUNCTION("""COMPUTED_VALUE"""),"") | X1: =IFERROR(__xludf.DUMMYFUNCTION("""COMPUTED_VALUE"""),"") | Y1: =IFERROR(__xludf.DUMMYFUNCTION("""COMPUTED_VALUE"""),"") | Z1: =IFERROR(__xludf.DUMMYFUNCTION("""COMPUTED_VALUE"""),"")
A2: =IFERROR(__xludf.DUMMYFUNCTION("""COMPUTED_VALUE"""),"another test again") -> another test again | B2: =IFERROR(__xludf.DUMMYFUNCTION("""COMPUTED_VALUE"""),"Open Items") -> Open Items | C2: =IFERROR(__xludf.DUMMYFUNCTION("""COMPUTED_VALUE"""),"Partner Management Activities") -> Partner Management Activities | E2: =IFERROR(__xludf.DUMMYFUNCTION("""COMPUTED_VALUE"""),1.1093054347E10) -> 11093054347 | F2: =IFERROR(__xludf.DUMMYFUNCTION("""COMPUTED_VALUE"""),9.791255941E9) -> 9791255941 | G2: =IFERROR(__xludf.DUMMYFUNCTION("""COMPUTED_VALUE"""),"In Progress") -> In Progress | H2: =IFERROR(__xludf.DUMMYFUNCTION("""COMPUTED_VALUE"""),"Eric Apse") -> Eric Apse | I2: =IFERROR(__xludf.DUMMYFUNCTION("""COMPUTED_VALUE"""),"Tim Kennedy") -> Tim Kennedy | J2: =IFERROR(__xludf.DUMMYFUNCTION("""COMPUTED_VALUE"""),"1. Urgent") -> 1. Urgent | K2: =IFERROR(__xludf.DUMMYFUNCTION("""COMPUTED_VALUE"""),"Referal") -> Referal | L2: =IFERROR(__xludf.DUMMYFUNCTION("""COMPUTED_VALUE"""),45698.0) -> 45698 | M2: =IFERROR(__xludf.DUMMYFUNCTION("""COMPUTED_VALUE"""),46028.0) -> 46028 | P2: =IFERROR(__xludf.DUMMYFUNCTION("""COMPUTED_VALUE"""),"just more test") -> just more test | R2: =IFERROR(__xludf.DUMMYFUNCTION("""COMPUTED_VALUE"""),"Partner Management Activities") -> Partner Management Activities
A3: =IFERROR(__xludf.DUMMYFUNCTION("""COMPUTED_VALUE"""),"Make sure your parter is certified asap") -> Make sure your parter is certified asap | B3: =IFERROR(__xludf.DUMMYFUNCTION("""COMPUTED_VALUE"""),"Open Items") -> Open Items | C3: =IFERROR(__xludf.DUMMYFUNCTION("""COMPUTED_VALUE"""),"Partner Management Activities") -> Partner Management Activities | E3: =IFERROR(__xludf.DUMMYFUNCTION("""COMPUTED_VALUE"""),1.0941024281E10) -> 10941024281 | F3: =IFERROR(__xludf.DUMMYFUNCTION("""COMPUTED_VALUE"""),9.791255941E9) -> 9791255941 | G3: =IFERROR(__xludf.DUMMYFUNCTION("""COMPUTED_VALUE"""),"In Progress") -> In Progress | H3: =IFERROR(__xludf.DUMMYFUNCTION("""COMPUTED_VALUE"""),"Eric Apse") -> Eric Apse | I3: =IFERROR(__xludf.DUMMYFUNCTION("""COMPUTED_VALUE"""),"Tim Kennedy") -> Tim Kennedy | J3: =IFERROR(__xludf.DUMMYFUNCTION("""COMPUTED_VALUE"""),"1. Urgent") -> 1. Urgent | K3: =IFERROR(__xludf.DUMMYFUNCTION("""COMPUTED_VALUE"""),"Partner Management") -> Partner Management | L3: =IFERROR(__xludf.DUMMYFUNCTION("""COMPUTED_VALUE"""),45698.0) -> 45698 | M3: =IFERROR(__xludf.DUMMYFUNCTION("""COMPUTED_VALUE"""),46036.0) -> 46036 | R3: =IFERROR(__xludf.DUMMYFUNCTION("""COMPUTED_VALUE"""),"Partner Management Activities") -> Partner Management Activities
A4: =IFERROR(__xludf.DUMMYFUNCTION("""COMPUTED_VALUE"""),"test") -> test | B4: =IFERROR(__xludf.DUMMYFUNCTION("""COMPUTED_VALUE"""),"Open Items") -> Open Items | C4: =IFERROR(__xludf.DUMMYFUNCTION("""COMPUTED_VALUE"""),"Partner Management Activities") -> Partner Management Activities | E4: =IFERROR(__xludf.DUMMYFUNCTION("""COMPUTED_VALUE"""),1.0809257698E10) -> 10809257698 | F4: =IFERROR(__xludf.DUMMYFUNCTION("""COMPUTED_VALUE"""),9.791255941E9) -> 9791255941 | G4: =IFERROR(__xludf.DUMMYFUNCTION("""COMPUTED_VALUE"""),"In Progress") -> In Progress | H4: =IFERROR(__xludf.DUMMYFUNCTION("""COMPUTED_VALUE"""),"Eric Apse") -> Eric Apse | I4: =IFERROR(__xludf.DUMMYFUNCTION("""COMPUTED_VALUE"""),"Tim Kennedy") -> Tim Kennedy | J4: =IFERROR(__xludf.DUMMYFUNCTION("""COMPUTED_VALUE"""),"5. N/A") -> 5. N/A | K4: =IFERROR(__xludf.DUMMYFUNCTION("""COMPUTED_VALUE"""),"TechAll Marketing") -> TechAll Marketing | L4: =IFERROR(__xludf.DUMMYFUNCTION("""COMPUTED_VALUE"""),45698.0) -> 45698 | M4: =IFERROR(__xludf.DUMMYFUNCTION("""COMPUTED_VALUE"""),46037.0) -> 46037 | R4: =IFERROR(__xludf.DUMMYFUNCTION("""COMPUTED_VALUE"""),"Partner Management Activities") -> Partner Management Activities
A5: =IFERROR(__xludf.DUMMYFUNCTION("""COMPUTED_VALUE"""),"test 2") -> test 2 | B5: =IFERROR(__xludf.DUMMYFUNCTION("""COMPUTED_VALUE"""),"Open Items") -> Open Items | C5: =IFERROR(__xludf.DUMMYFUNCTION("""COMPUTED_VALUE"""),"Partner Management Activities") -> Partner Management Activities | E5: =IFERROR(__xludf.DUMMYFUNCTION("""COMPUTED_VALUE"""),1.0813317258E10) -> 10813317258 | F5: =IFERROR(__xludf.DUMMYFUNCTION("""COMPUTED_VALUE"""),9.791255941E9) -> 9791255941 | G5: =IFERROR(__xludf.DUMMYFUNCTION("""COMPUTED_VALUE"""),"In Progress") -> In Progress | H5: =IFERROR(__xludf.DUMMYFUNCTION("""COMPUTED_VALUE"""),"Eric Apse") -> Eric Apse | I5: =IFERROR(__xludf.DUMMYFUNCTION("""COMPUTED_VALUE"""),"Tim Kennedy") -> Tim Kennedy | J5: =IFERROR(__xludf.DUMMYFUNCTION("""COMPUTED_VALUE"""),"1. Urgent") -> 1. Urgent | K5: =IFERROR(__xludf.DUMMYFUNCTION("""COMPUTED_VALUE"""),"Marketplace") -> Marketplace | L5: =IFERROR(__xludf.DUMMYFUNCTION("""COMPUTED_VALUE"""),45698.0) -> 45698 | M5: =IFERROR(__xludf.DUMMYFUNCTION("""COMPUTED_VALUE"""),46033.0) -> 46033 | R5: =IFERROR(__xludf.DUMMYFUNCTION("""COMPUTED_VALUE"""),"Partner Management Activities") -> Partner Management Activities
A6: =IFERROR(__xludf.DUMMYFUNCTION("""COMPUTED_VALUE"""),"test 3") -> test 3 | B6: =IFERROR(__xludf.DUMMYFUNCTION("""COMPUTED_VALUE"""),"Open Items") -> Open Items | C6: =IFERROR(__xludf.DUMMYFUNCTION("""COMPUTED_VALUE"""),"Partner Management Activities") -> Partner Management Activities | E6: =IFERROR(__xludf.DUMMYFUNCTION("""COMPUTED_VALUE"""),1.0813553846E10) -> 10813553846 | F6: =IFERROR(__xludf.DUMMYFUNCTION("""COMPUTED_VALUE"""),9.791255941E9) -> 9791255941 | G6: =IFERROR(__xludf.DUMMYFUNCTION("""COMPUTED_VALUE"""),"In Progress") -> In Progress | H6: =IFERROR(__xludf.DUMMYFUNCTION("""COMPUTED_VALUE"""),"Eric Apse") -> Eric Apse | I6: =IFERROR(__xludf.DUMMYFUNCTION("""COMPUTED_VALUE"""),"Tim Kennedy") -> Tim Kennedy | J6: =IFERROR(__xludf.DUMMYFUNCTION("""COMPUTED_VALUE"""),"1. Urgent") -> 1. Urgent | K6: =IFERROR(__xludf.DUMMYFUNCTION("""COMPUTED_VALUE"""),"TechAll Marketing") -> TechAll Marketing | L6: =IFERROR(__xludf.DUMMYFUNCTION("""COMPUTED_VALUE"""),45698.0) -> 45698 | M6: =IFERROR(__xludf.DUMMYFUNCTION("""COMPUTED_VALUE"""),46038.0) -> 46038 | R6: =IFERROR(__xludf.DUMMYFUNCTION("""COMPUTED_VALUE"""),"Partner Management Activities") -> Partner Management Activities
A7: =IFERROR(__xludf.DUMMYFUNCTION("""COMPUTED_VALUE"""),"test3 new") -> test3 new | B7: =IFERROR(__xludf.DUMMYFUNCTION("""COMPUTED_VALUE"""),"Open Items") -> Open Items | C7: =IFERROR(__xludf.DUMMYFUNCTION("""COMPUTED_VALUE"""),"Partner Management Activities") -> Partner Management Activities | E7: =IFERROR(__xludf.DUMMYFUNCTION("""COMPUTED_VALUE"""),1.0813549497E10) -> 10813549497 | F7: =IFERROR(__xludf.DUMMYFUNCTION("""COMPUTED_VALUE"""),9.791255941E9) -> 9791255941 | G7: =IFERROR(__xludf.DUMMYFUNCTION("""COMPUTED_VALUE"""),"Halted") -> Halted | H7: =IFERROR(__xludf.DUMMYFUNCTION("""COMPUTED_VALUE"""),"Eric Apse") -> Eric Apse | I7: =IFERROR(__xludf.DUMMYFUNCTION("""COMPUTED_VALUE"""),"Tim Kennedy") -> Tim Kennedy | J7: =IFERROR(__xludf.DUMMYFUNCTION("""COMPUTED_VALUE"""),"1. Urgent") -> 1. Urgent | K7: =IFERROR(__xludf.DUMMYFUNCTION("""COMPUTED_VALUE"""),"Marketplace") -> Marketplace | L7: =IFERROR(__xludf.DUMMYFUNCTION("""COMPUTED_VALUE"""),45698.0) -> 45698 | M7: =IFERROR(__xludf.DUMMYFUNCTION("""COMPUTED_VALUE"""),46038.0) -> 46038 | R7: =IFERROR(__xludf.DUMMYFUNCTION("""COMPUTED_VALUE"""),"Partner Management Activities") -> Partner Management Activities
A8: =IFERROR(__xludf.DUMMYFUNCTION("""COMPUTED_VALUE"""),"tim test") -> tim test | B8: =IFERROR(__xludf.DUMMYFUNCTION("""COMPUTED_VALUE"""),"Open Items") -> Open Items | C8: =IFERROR(__xludf.DUMMYFUNCTION("""COMPUTED_VALUE"""),"Partner Management Activities") -> Partner Management Activities | E8: =IFERROR(__xludf.DUMMYFUNCTION("""COMPUTED_VALUE"""),1.0819625182E10) -> 10819625182 | F8: =IFERROR(__xludf.DUMMYFUNCTION("""COMPUTED_VALUE"""),9.791255941E9) -> 9791255941 | G8: =IFERROR(__xludf.DUMMYFUNCTION("""COMPUTED_VALUE"""),"Blockers") -> Blockers | H8: =IFERROR(__xludf.DUMMYFUNCTION("""COMPUTED_VALUE"""),"Tim Kennedy") -> Tim Kennedy | I8: =IFERROR(__xludf.DUMMYFUNCTION("""COMPUTED_VALUE"""),"Tim Kennedy") -> Tim Kennedy | J8: =IFERROR(__xludf.DUMMYFUNCTION("""COMPUTED_VALUE"""),"1. Urgent") -> 1. Urgent | K8: =IFERROR(__xludf.DUMMYFUNCTION("""COMPUTED_VALUE"""),"Partner Management") -> Partner Management | L8: =IFERROR(__xludf.DUMMYFUNCTION("""COMPUTED_VALUE"""),45698.0) -> 45698 | M8: =IFERROR(__xludf.DUMMYFUNCTION("""COMPUTED_VALUE"""),46029.0) -> 46029 | P8: =IFERROR(__xludf.DUMMYFUNCTION("""COMPUTED_VALUE"""),"none") -> none | R8: =IFERROR(__xludf.DUMMYFUNCTION("""COMPUTED_VALUE"""),"Partner Management Activities") -> Partner Management Activities
A9: =IFERROR(__xludf.DUMMYFUNCTION("""COMPUTED_VALUE"""),"test") -> test | B9: =IFERROR(__xludf.DUMMYFUNCTION("""COMPUTED_VALUE"""),"Open Items") -> Open Items | C9: =IFERROR(__xludf.DUMMYFUNCTION("""COMPUTED_VALUE"""),"Tech Ops Activities") -> Tech Ops Activities | E9: =IFERROR(__xludf.DUMMYFUNCTION("""COMPUTED_VALUE"""),1.0813055615E10) -> 10813055615 | F9: =IFERROR(__xludf.DUMMYFUNCTION("""COMPUTED_VALUE"""),9.79127239E9) -> 9791272390 | G9: =IFERROR(__xludf.DUMMYFUNCTION("""COMPUTED_VALUE"""),"In Progress") -> In Progress | H9: =IFERROR(__xludf.DUMMYFUNCTION("""COMPUTED_VALUE"""),"Kayla Page") -> Kayla Page | I9: =IFERROR(__xludf.DUMMYFUNCTION("""COMPUTED_VALUE"""),"Tim Kennedy") -> Tim Kennedy | J9: =IFERROR(__xludf.DUMMYFUNCTION("""COMPUTED_VALUE"""),"1. Urgent") -> 1. Urgent | K9: =IFERROR(__xludf.DUMMYFUNCTION("""COMPUTED_VALUE"""),"Validation") -> Validation | L9: =IFERROR(__xludf.DUMMYFUNCTION("""COMPUTED_VALUE"""),45698.0) -> 45698 | M9: =IFERROR(__xludf.DUMMYFUNCTION("""COMPUTED_VALUE"""),46052.0) -> 46052 | P9: =IFERROR(__xludf.DUMMYFUNCTION("""COMPUTED_VALUE"""),"none") -> none | R9: =IFERROR(__xludf.DUMMYFUNCTION("""COMPUTED_VALUE"""),"Tech Ops Activities") -> Tech Ops Activities
A10: =IFERROR(__xludf.DUMMYFUNCTION("""COMPUTED_VALUE"""),"Test") -> Test | B10: =IFERROR(__xludf.DUMMYFUNCTION("""COMPUTED_VALUE"""),"Open Items") -> Open Items | C10: =IFERROR(__xludf.DUMMYFUNCTION("""COMPUTED_VALUE"""),"Marketplace Activities") -> Marketplace Activities | E10: =IFERROR(__xludf.DUMMYFUNCTION("""COMPUTED_VALUE"""),1.1092783913E10) -> 11092783913 | F10: =IFERROR(__xludf.DUMMYFUNCTION("""COMPUTED_VALUE"""),1.837501336E10) -> 18375013360 | G10: =IFERROR(__xludf.DUMMYFUNCTION("""COMPUTED_VALUE"""),"In Progress") -> In Progress | H10: =IFERROR(__xludf.DUMMYFUNCTION("""COMPUTED_VALUE"""),"Richard Pauly") -> Richard Pauly | I10: =IFERROR(__xludf.DUMMYFUNCTION("""COMPUTED_VALUE"""),"Tim Kennedy") -> Tim Kennedy | J10: =IFERROR(__xludf.DUMMYFUNCTION("""COMPUTED_VALUE"""),"1. Urgent") -> 1. Urgent | K10: =IFERROR(__xludf.DUMMYFUNCTION("""COMPUTED_VALUE"""),"Partner Management") -> Partner Management | L10: =IFERROR(__xludf.DUMMYFUNCTION("""COMPUTED_VALUE"""),45698.0) -> 45698 | M10: =IFERROR(__xludf.DUMMYFUNCTION("""COMPUTED_VALUE"""),46052.0) -> 46052 | P10: =IFERROR(__xludf.DUMMYFUNCTION("""COMPUTED_VALUE"""),"test") -> test | R10: =IFERROR(__xludf.DUMMYFUNCTION("""COMPUTED_VALUE"""),"Marketplace Activities") -> Marketplace Activities

Sheet GW_MarketplaceActivities
A1: Item Name | B1: Group | C1: Board Name | D1: Partner Name | E1: Monday Item ID | F1: Board ID | G1: Activity Status | H1: Owner | I1: Assigned To | J1: Importance | K1: Activity Type | L1: Date Created | M1: Date Due | N1: Actual Completion | O1: Files | P1: Comments/Notes | Q1: Subitems | R1: Tech Board Type | S1: Alliance Manager
A2: Test | B2: Open Items | C2: Marketplace Activities | E2: 11092783913 | F2: 18375013360 | G2: In Progress | H2: Richard Pauly | I2: Tim Kennedy | J2: 1. Urgent | K2: Partner Management | L2: 45698 | M2: 46052 | P2: test | R2: Marketplace Activities

Sheet MarketingApproval
A1: Item Name | B1: Group | C1: Board Name | D1: Partner Name | E1: Monday Item ID | F1: Board ID | G1: Subitems | H1: Event URL | I1: Priority | J1: Funding Type | K1: Overall Status | L1: AllianceManager | M1: Partner | N1: Requesting Department | O1: Cost | P1: Date and Location | Q1: Start Date | R1: Request Type | S1: Urgency | T1: Number of Meetings or Receptions | U1: Total Audience | V1: Expected Attendance | W1: Speaking Opportunity | X1: Justification Link | Y1: Brand Details | Z1: Create Date | AA1: Scope Document Public URL | AB1: Alliance Manager | AC1: Final Approval Date | AD1: Eric Decision | AE1: Marketing Decision | AF1: Will Decision | AG1: Scope Document Public URL | AH1: Alliance Manager
A2: Earnix 2026 Excelerate | B2: Incoming | C2: Marketing Events Approval Requests | D2: Marketing Team | E2: 9759595231 | F2: 9710279044 | I2: Priority 1 | J2: Partner Funding Request | K2: Submitted | L2: Tim Kennedy | M2: Earnix | N2: Partner Management | O2: 20000 | P2: London 2026 | Q2: 46280 | R2: Live Event | S2: Normal | T2: 4 | U2: 300 | V2: 300 | W2: No | Y2: Logo on a booth
A3: Live event for AWS | B3: Incoming | C3: Marketing Events Approval Requests | D3: Marketing Team | E3: 9779348217 | F3: 9710279044 | I3: Priority 1 | J3: Partner Funding Request | K3: Approved | N3: Partner Management | O3: 10000 | R3: Live Event | S3: Normal | Z3: 45877
A4: AAIS | B4: Incoming | C4: Marketing Events Approval Requests | D4: Marketing Team | E4: 9766632601 | F4: 9710279044 | H4: https://events.aaisonline.com/2025aaismaineventsponsorships/Opportunities | I4: Priority 1 | J4: Partner Funding Request | K4: Approved | L4: Aaron Shaw | M4: AAIS | N4: Partner Management | O4: 14000 | P4: April 6-8 ClearWater FLA | Q4: 45753 | R4: Live Event | S4: Normal | T4: 3 in total = 1 potential carrier (Insurors Indemnity) 2 vanguard prospects (FireFly + Adaptify), 1 existing partner(P*K) | U4: 300-400 | V4: 300 | W4: No | Y4: Table in the Exhibit Hall with Marketplace branding. Guidewire Corp logo during Keynote speaker and networking break sessions
A5: InsurtechLIVE Networking Event in Australia (Ketaki Padhye to complete) Approved via Will Murphy, leadership meeting, 12/19. | B5: Incoming | C5: Marketing Events Approval Requests | D5: Marketing Team | E5: 9766632719 | F5: 9710279044 | I5: Priority 1 | J5: Partner Funding Request | K5: Approved | L5: Ketaki Padehye | N5: Marketing | O5: 6050 | R5: Live Event | S5: Normal
A6: Workers Comp IV Pitch Day (with GIF or Insurtech Insights) | B6: Incoming | C6: Marketing Events Approval Requests | D6: Marketing Team | E6: 9766632803 | F6: 9710279044 | I6: Priority 1 | J6: Partner Funding Request | K6: Approved | L6: Eric Apse | N6: Marketing | O6: 25000 | P6: 40368 | Q6: 45847 | R6: Live Event | S6: Normal
A7: Nearmap Execitve Summit with GW Sponsor | B7: Incoming | C7: Marketing Events Approval Requests | D7: Marketing Team | E7: 9766632873 | F7: 9710279044 | I7: Priority 1 | J7: Partner Funding Request | K7: Approved | L7: Ketaki Padehye | M7: Nearmap US, Inc. | N7: Partner Management | O7: 22000 | R7: Live Event | S7: Normal
A8: APAC MYSU | B8: Incoming | C8: Marketing Events Approval Requests | D8: Marketing Team | E8: 9766632936 | F8: 9710279044 | I8: Priority 1 | J8: Partner Funding Request | K8: Approved | O8: 0 | R8: Live Event | S8: Normal
A9: Box Works | B9: Incoming | C9: Marketing Events Approval Requests | D9: Marketing Team | E9: 9766633017 | F9: 9710279044 | H9: BOX | I9: Priority 1 | J9: Partner Funding Request | K9: Approved | L9: Tim Kennedy | M9: Box | N9: Partner Management | O9: 5000 | P9: November 12 -13 , 2024 San Francisco, CA | Q9: 45973 | R9: Live Event | S9: Normal
A10: CoreLogic Customer Event | B10: Incoming | C10: Marketing Events Approval Requests | D10: Marketing Team | E10: 9766633088 | F10: 9710279044 | H10: CoreLogic | I10: Priority 1 | J10: Partner Funding Request | K10: Approved | L10: Tim Kennedy | M10: CoreLogic | N10: Partner Management | O10: 16000 | P10: March 23 -25, 2025 Los Angeles, CA (rescheduled) | Q10: 45739 | R10: Live Event | S10: Normal | U10: InsuranceSuite Customers | V10: 1200 | W10: No speaking role | Y10: Logo will appear on a booth
A11: Developer Summit + hackathon | B11: Incoming | C11: Marketing Events Approval Requests | D11: Marketing Team | E11: 9766633185 | F11: 9710279044 | I11: Priority 1 | J11: Partner Funding Request | K11: Approved | N11: Marketplace | O11: 80000 | R11: Live Event | S11: Normal
A12: Earnix | B12: Incoming | C12: Marketing Events Approval Requests | D12: Marketing Team | E12: 9766633269 | F12: 9710279044 | H12: https://www.excelerate.earnix.com/ | I12: Priority 1 | J12: Partner Funding Request | K12: Approved | L12: Tim Kennedy | M12: Earnix | N12: Partner Management | O12: 25000 | P12: September 25-26, 2024. London | Q12: 45925 | R12: Live Event | S12: Normal | U12: PolicyCenter and iNow customers | V12: 500 | W12: Christina Lucas is a keynote | Y12: Logo will appear on booth
A13: WTW - event pending | B13: Incoming | C13: Marketing Events Approval Requests | D13: Marketing Team | E13: 9766633364 | F13: 9710279044 | I13: Priority 3 | J13: Partner Funding Request | K13: Approved | L13: Tim Kennedy | M13: WTW | N13: Partner Management | O13: 0 | P13: London.. summer 2025 | Q13: 45809 | R13: Live Event | S13: Normal | V13: 500 | W13: No | Y13: None
A14: EMEA IV Pitch Day (with GIF or Insurtech Insights, London Markets) | B14: Incoming | C14: Marketing Events Approval Requests | D14: Marketing Team | E14: 9766633444 | F14: 9710279044 | I14: Priority 1 | J14: Partner Funding Request | K14: Approved | L14: Eric Apse | N14: Marketing | O14: 20000 | P14: June 26th | Q14: 45834 | R14: Live Event | S14: Normal
A15: EMEA Mid year sales update MYSU | B15: Incoming | C15: Marketing Events Approval Requests | D15: Marketing Team | E15: 9766633524 | F15: 9710279044 | I15: Priority 1 | J15: Partner Funding Request | K15: Approved | N15: Marketing | O15: 0 | R15: Live Event | S15: Normal
A16: Evolution IQ | B16: Incoming | C16: Marketing Events Approval Requests | D16: Marketing Team | E16: 9766633594 | F16: 9710279044 | H16: https://www.wcrinet.org/news/news_info/save-the-date-2025-wcri-issues-research-conference-march-6-7-in-phoenix-az | I16: Priority 1 | J16: Partner Funding Request | K16: Approved | L16: Gregg Rabenold | M16: EvolutionIQ | N16: Partner Management | O16: 5000 | P16: Workers Compensation Research Institute Conference, March 6- 7 Phoenix | Q16: 45722 | R16: Live Event | S16: Normal | T16: Dinner with 20 customers/prospects | U16: Joint customers and prospects | V16: 15 - 20 | W16: Dinners / social events around other EIQ or GW participting events | Y16: Sales pitch and networking
A17: Evolution IQ | B17: Incoming | C17: Marketing Events Approval Requests | D17: Marketing Team | E17: 9766633661 | F17: 9710279044 | H17: https://www.ncci.com/Articles/Pages/Insights-AIS-Save-the-Date-2025.aspx | I17: Priority 1 | J17: Partner Funding Request | K17: Approved | L17: Gregg Rabenold | M17: EvolutionIQ | N17: Partner Management | O17: 5000 | P17: National Council on Compensation Insurance, May 12 -13, 2025 | Q17: 45789 | R17: Live Event | S17: Normal | T17: Dinner with 20 customers/prospects | U17: Joint customers and prospects | V17: 15 - 20 | W17: Dinners / social events around other EIQ or GW participting events | Y17: Sales pitch and networking
A18: Evolution IQ | B18: Incoming | C18: Marketing Events Approval Requests | D18: Marketing Team | E18: 9766633725 | F18: 9710279044 | I18: Priority 1 | J18: Partner Funding Request | K18: Approved | L18: Gregg Rabenold | M18: EvolutionIQ | N18: Partner Management | O18: 5000 | P18: TBD - (NYC or Chicago) | R18: Live Event | S18: Normal | T18: Dinner with 20 customers/prospects | U18: Joint customers and prospects | V18: 15-20
A19: Executive Symposium | B19: Incoming | C19: Marketing Events Approval Requests | D19: Marketing Team | E19: 9766633791 | F19: 9710279044 | I19: Priority 1 | J19: Partner Funding Request | K19: Approved | N19: Marketing | O19: 0 | Q19: 45736 | R19: Live Event | S19: Normal
A20: Genesys | B20: Incoming | C20: Marketing Events Approval Requests | D20: Marketing Team | E20: 9766633845 | F20: 9710279044 | I20: Priority 1 | J20: Partner Funding Request | K20: Approved | L20: Gregg Rabenold | M20: Genesys Cloud Services, Inc. | N20: Partner Management | O20: 5000 | P20: TBD - working on co-marketing event ideas | R20: Live Event | S20: Normal
A21: Genesys conference | B21: Incoming | C21: Marketing Events Approval Requests | D21: Marketing Team | E21: 9766633917 | F21: 9710279044 | H21: https://www.genesys.com/xperience | I21: Priority 1 | J21: Partner Funding Request | K21: Approved | L21: Gregg Rabenold | M21: Genesys Cloud Services, Inc. | N21: Partner Management | O21: 20000 | P21: September 8-10 Nashville | Q21: 45908 | R21: Live Event | S21: Normal | U21: Joint customers and prospects | V21: 3000 (200 insurers) | W21: Panel speaking opportunity, Gregg R to participate | Y21: Small booth, banner and meeting recognition
A22: Insurtech (Las Vegas) - IV Pitch Day | B22: Incoming | C22: Marketing Events Approval Requests | D22: Marketing Team | E22: 9766633969 | F22: 9710279044 | I22: Priority 1 | J22: Partner Funding Request | K22: Approved | L22: Eric Apse | N22: Partner Management | O22: 30000 | R22: Live Event | S22: Normal
A23: Insurtech Hartford | B23: Incoming | C23: Marketing Events Approval Requests | D23: Marketing Team | E23: 9766634060 | F23: 9710279044 | I23: Priority 1 | J23: Partner Funding Request | K23: Approved | L23: Eric Apse | N23: Partner Management | O23: 5000 | R23: Live Event | S23: Normal
A24: Insurtech Innovators - Nordics | B24: Incoming | C24: Marketing Events Approval Requests | D24: Marketing Team | E24: 9766632612 | F24: 9710279044 | I24: Priority 1 | J24: Partner Funding Request | K24: Approved | N24: Marketing | R24: Live Event | S24: Normal
A25: Insurtech Insights London - Show Customer Marketplace | B25: Incoming | C25: Marketing Events Approval Requests | D25: Marketing Team | E25: 9766632692 | F25: 9710279044 | I25: Priority 1 | J25: Partner Funding Request | K25: Approved | L25: Eric Apse | N25: Marketing | R25: Live Event | S25: Normal
A26: Invoice Cloud / Guidewire | B26: Incoming | C26: Marketing Events Approval Requests | D26: Marketing Team | E26: 9766632771 | F26: 9710279044 | I26: Priority 1 | J26: Partner Funding Request | K26: Approved | L26: Kelly Clayton | N26: Partner Management | O26: 15000 | P26: 46249.792 | Q26: 45884 | R26: Live Event | S26: Normal | T26: Bourbon Tasting - Behind the barrel
A27: ITC Trade Show Vegas - Partner Recruitment | B27: Incoming | C27: Marketing Events Approval Requests | D27: Marketing Team | E27: 9766632892 | F27: 9710279044 | H27: https://vegas.insuretechconnect.com/ | I27: Priority 1 | J27: Partner Funding Request | K27: Approved | L27: Lisa Vingerhoet, Gregg Rabenold | N27: Marketing | O27: 44295 | P27: Las Vegas, 10/15- 10/17 | Q27: 45945 | R27: Live Event | S27: Normal | T27: Nearmap reception and EIQ
A28: IVANS | B28: Incoming | C28: Marketing Events Approval Requests | D28: Marketing Team | E28: 9766632957 | F28: 9710279044 | H28: Link | I28: Priority 1 | J28: Partner Funding Request | K28: Approved | L28: Gregg Rabenold | M28: Applied Systems Inc | N28: Partner Management | O28: 5000 | P28: Ivans Insuretech Boston May 15th | Q28: 45792 | R28: Live Event | S28: Normal | T28: Conference | U28: 3 - 500
A29: Marketplace Lunch and Learn (in planning) | B29: Incoming | C29: Marketing Events Approval Requests | D29: Marketing Team | E29: 9766633051 | F29: 9710279044 | I29: Priority 1 | J29: Partner Funding Request | K29: Approved | N29: Marketplace | R29: Live Event | S29: Normal
A30: One Inc Customer Conference | B30: Incoming | C30: Marketing Events Approval Requests | D30: Marketing Team | E30: 9766633144 | F30: 9710279044 | I30: Priority 1 | J30: Partner Funding Request | K30: Approved | L30: Lisa Vingerhoet | M30: One Inc | N30: Partner Management | O30: 50000 | P30: Marco Island, May 7-9 | Q30: 45784 | R30: Live Event | S30: Normal
A31: One Inc Masters Event | B31: Incoming | C31: Marketing Events Approval Requests | D31: Marketing Team | E31: 9766633218 | F31: 9710279044 | I31: Priority 1 | J31: Partner Funding Request | K31: Approved | L31: Lisa Vingerhoet | M31: One Inc | N31: Partner Management | O31: 74950 | P31: Augusta GA, April 7 - 13 | Q31: 45754 | R31: Live Event | S31: Normal | U31: Customer execs | V31: 10 customers - Chubb, PMA, West Bend, Aspire, The Hartford, TMHCC, EMC, Encova | W31: N/A
A32: Re:Invent Customer Dinner | B32: Incoming | C32: Marketing Events Approval Requests | D32: Marketing Team | E32: 9766633323 | F32: 9710279044 | I32: Priority 1 | J32: Partner Funding Request | K32: Approved | L32: Paul Harper | N32: Partner Management | R32: Live Event | S32: Normal
A33: Re:Invent Executive Track Dinner | B33: Incoming | C33: Marketing Events Approval Requests | D33: Marketing Team | E33: 9766633397 | F33: 9710279044 | I33: Priority 1 | J33: Partner Funding Request | K33: Approved | L33: Paul Harper | N33: Partner Management | R33: Live Event | S33: Normal
A34: Smart AMER | B34: Incoming | C34: Marketing Events Approval Requests | D34: Marketing Team | E34: 9766633454 | F34: 9710279044 | H34: https://www.smartcommunications.com/resources/events/innovate/ | I34: Priority 1 | J34: Partner Funding Request | K34: Approved | L34: Lisa Vingerhoet | M34: SmartComms LLC | N34: Partner Management | O34: 10000 | P34: New Orleans, April 23-25, 2025 | Q34: 45770 | R34: Live Event | S34: Normal | T34: 12 | U34: 150 | W34: Yes - Future of Claims break out to insurance attendees | Y34: Marketplace logo at the table and on all materials
